Workbook

Sheet Donor Data (Task 1,2,3,4, 6)
A1: June 2023 — Donor Submission Data (Detail) | Millennium Organisation | K1: =AVERAGE(H4:H274) -> 0.69840473
A2: Owner | B2: Age Group | C2: Submission | D2: Contribution % | E2: Debit 1 | F2: Debit 2 | G2: Debit 3 | H2: Debit 3 % | I2: Performance (25-27)
A3: Abhijeet D | B3: BELOW 25 | C3: 1 | D3: =IFERROR(C3/'Owner Totals (Pivot)(Task 4)'!B4,"") -> 0.0042372881 | E3: 1 | F3: 1 | G3: 0 | H3: =IFERROR(G3/C3,"") -> 0 | K3: =SUMPRODUCT(MAX(($A$4:$A$274=A3)*$D$4:$D$274)) -> 0.22033898
A4: Abhijeet D | B4: 25-27 | C4: 52 | D4: =IFERROR(C4/'Owner Totals (Pivot)(Task 4)'!B4,"") -> 0.22033898 | E4: 49 | F4: 40 | G4: 38 | H4: =IFERROR(G4/C4,"") -> 0.73076923 | I4: Average | K4: =SUMPRODUCT(MAX(($A$4:$A$274=A4)*$D$4:$D$274)) -> 0.22033898
A5: Abhijeet D | B5: 28-29 | C5: 27 | D5: =IFERROR(C5/'Owner Totals (Pivot)(Task 4)'!B4,"") -> 0.11440678 | E5: 22 | F5: 20 | G5: 19 | H5: =IFERROR(G5/C5,"") -> 0.7037037 | K5: =SUMPRODUCT(MAX(($A$4:$A$274=A5)*$D$4:$D$274)) -> 0.22033898
A6: Abhijeet D | B6: 30-34 | C6: 50 | D6: =IFERROR(C6/'Owner Totals (Pivot)(Task 4)'!B4,"") -> 0.21186441 | E6: 46 | F6: 38 | G6: 38 | H6: =IFERROR(G6/C6,"") -> 0.76 | K6: =SUMPRODUCT(MAX(($A$4:$A$274=A6)*$D$4:$D$274)) -> 0.22033898
A7: Abhijeet D | B7: 35-39 | C7: 38 | D7: =IFERROR(C7/'Owner Totals (Pivot)(Task 4)'!B4,"") -> 0.16101695 | E7: 37 | F7: 35 | G7: 34 | H7: =IFERROR(G7/C7,"") -> 0.89473684 | K7: =SUMPRODUCT(MAX(($A$4:$A$274=A7)*$D$4:$D$274)) -> 0.22033898
A8: Abhijeet D | B8: 40-44 | C8: 38 | D8: =IFERROR(C8/'Owner Totals (Pivot)(Task 4)'!B4,"") -> 0.16101695 | E8: 33 | F8: 28 | G8: 27 | H8: =IFERROR(G8/C8,"") -> 0.71052632 | K8: =SUMPRODUCT(MAX(($A$4:$A$274=A8)*$D$4:$D$274)) -> 0.22033898
A9: Abhijeet D | B9: 45-49 | C9: 17 | D9: =IFERROR(C9/'Owner Totals (Pivot)(Task 4)'!B4,"") -> 0.072033898 | E9: 14 | F9: 13 | G9: 13 | H9: =IFERROR(G9/C9,"") -> 0.76470588 | K9: =SUMPRODUCT(MAX(($A$4:$A$274=A9)*$D$4:$D$274)) -> 0.22033898
A10: Abhijeet D | B10: 50+ | C10: 14 | D10: =IFERROR(C10/'Owner Totals (Pivot)(Task 4)'!B4,"") -> 0.059322034 | E10: 14 | F10: 14 | G10: 14 | H10: =IFERROR(G10/C10,"") -> 1 | K10: =SUMPRODUCT(MAX(($A$4:$A$274=A10)*$D$4:$D$274)) -> 0.22033898
A11: Adnan Kantawala | B11: 25-27 | C11: 20 | D11: =IFERROR(C11/'Owner Totals (Pivot)(Task 4)'!B5,"") -> 0.1754386 | E11: 16 | F11: 11 | G11: 10 | H11: =IFERROR(G11/C11,"") -> 0.5 | I11: Needs Attention | K11: =SUMPRODUCT(MAX(($A$4:$A$274=A11)*$D$4:$D$274)) -> 0.27192982
A12: Adnan Kantawala | B12: 28-29 | C12: 15 | D12: =IFERROR(C12/'Owner Totals (Pivot)(Task 4)'!B5,"") -> 0.13157895 | E12: 11 | F12: 8 | G12: 7 | H12: =IFERROR(G12/C12,"") -> 0.46666667 | K12: =SUMPRODUCT(MAX(($A$4:$A$274=A12)*$D$4:$D$274)) -> 0.27192982
A13: Adnan Kantawala | B13: 30-34 | C13: 31 | D13: =IFERROR(C13/'Owner Totals (Pivot)(Task 4)'!B5,"") -> 0.27192982 | E13: 23 | F13: 17 | G13: 17 | H13: =IFERROR(G13/C13,"") -> 0.5483871 | K13: =SUMPRODUCT(MAX(($A$4:$A$274=A13)*$D$4:$D$274)) -> 0.27192982
A14: Adnan Kantawala | B14: 35-39 | C14: 16 | D14: =IFERROR(C14/'Owner Totals (Pivot)(Task 4)'!B5,"") -> 0.14035088 | E14: 13 | F14: 11 | G14: 8 | H14: =IFERROR(G14/C14,"") -> 0.5 | K14: =SUMPRODUCT(MAX(($A$4:$A$274=A14)*$D$4:$D$274)) -> 0.27192982
A15: Adnan Kantawala | B15: 40-44 | C15: 15 | D15: =IFERROR(C15/'Owner Totals (Pivot)(Task 4)'!B5,"") -> 0.13157895 | E15: 14 | F15: 14 | G15: 9 | H15: =IFERROR(G15/C15,"") -> 0.6 | K15: =SUMPRODUCT(MAX(($A$4:$A$274=A15)*$D$4:$D$274)) -> 0.27192982
A16: Adnan Kantawala | B16: 45-49 | C16: 7 | D16: =IFERROR(C16/'Owner Totals (Pivot)(Task 4)'!B5,"") -> 0.061403509 | E16: 7 | F16: 7 | G16: 6 | H16: =IFERROR(G16/C16,"") -> 0.85714286 | K16: =SUMPRODUCT(MAX(($A$4:$A$274=A16)*$D$4:$D$274)) -> 0.27192982
A17: Adnan Kantawala | B17: 50+ | C17: 10 | D17: =IFERROR(C17/'Owner Totals (Pivot)(Task 4)'!B5,"") -> 0.087719298 | E17: 9 | F17: 8 | G17: 8 | H17: =IFERROR(G17/C17,"") -> 0.8 | K17: =SUMPRODUCT(MAX(($A$4:$A$274=A17)*$D$4:$D$274)) -> 0.27192982
A18: Ajay M | B18: BELOW 25 | C18: 1 | D18: =IFERROR(C18/'Owner Totals (Pivot)(Task 4)'!B6,"") -> 0.0096153846 | E18: 1 | F18: 0 | G18: 0 | H18: =IFERROR(G18/C18,"") -> 0 | K18: =SUMPRODUCT(MAX(($A$4:$A$274=A18)*$D$4:$D$274)) -> 0.36538462
A19: Ajay M | B19: 25-27 | C19: 38 | D19: =IFERROR(C19/'Owner Totals (Pivot)(Task 4)'!B6,"") -> 0.36538462 | E19: 30 | F19: 20 | G19: 19 | H19: =IFERROR(G19/C19,"") -> 0.5 | I19: Needs Attention | K19: =SUMPRODUCT(MAX(($A$4:$A$274=A19)*$D$4:$D$274)) -> 0.36538462
A20: Ajay M | B20: 28-29 | C20: 12 | D20: =IFERROR(C20/'Owner Totals (Pivot)(Task 4)'!B6,"") -> 0.11538462 | E20: 10 | F20: 9 | G20: 7 | H20: =IFERROR(G20/C20,"") -> 0.58333333 | K20: =SUMPRODUCT(MAX(($A$4:$A$274=A20)*$D$4:$D$274)) -> 0.36538462
A21: Ajay M | B21: 30-34 | C21: 32 | D21: =IFERROR(C21/'Owner Totals (Pivot)(Task 4)'!B6,"") -> 0.30769231 | E21: 29 | F21: 25 | G21: 25 | H21: =IFERROR(G21/C21,"") -> 0.78125 | K21: =SUMPRODUCT(MAX(($A$4:$A$274=A21)*$D$4:$D$274)) -> 0.36538462
A22: Ajay M | B22: 35-39 | C22: 13 | D22: =IFERROR(C22/'Owner Totals (Pivot)(Task 4)'!B6,"") -> 0.125 | E22: 10 | F22: 9 | G22: 8 | H22: =IFERROR(G22/C22,"") -> 0.61538462 | K22: =SUMPRODUCT(MAX(($A$4:$A$274=A22)*$D$4:$D$274)) -> 0.36538462
A23: Ajay M | B23: 40-44 | C23: 5 | D23: =IFERROR(C23/'Owner Totals (Pivot)(Task 4)'!B6,"") -> 0.048076923 | E23: 5 | F23: 5 | G23: 5 | H23: =IFERROR(G23/C23,"") -> 1 | K23: =SUMPRODUCT(MAX(($A$4:$A$274=A23)*$D$4:$D$274)) -> 0.36538462
A24: Ajay M | B24: 45-49 | C24: 3 | D24: =IFERROR(C24/'Owner Totals (Pivot)(Task 4)'!B6,"") -> 0.028846154 | E24: 2 | F24: 2 | G24: 2 | H24: =IFERROR(G24/C24,"") -> 0.66666667 | K24: =SUMPRODUCT(MAX(($A$4:$A$274=A24)*$D$4:$D$274)) -> 0.36538462
A25: Althaf A | B25: BELOW 25 | C25: 1 | D25: =IFERROR(C25/'Owner Totals (Pivot)(Task 4)'!B7,"") -> 0.0023584906 | E25: 0 | F25: 0 | G25: 0 | H25: =IFERROR(G25/C25,"") -> 0 | K25: =SUMPRODUCT(MAX(($A$4:$A$274=A25)*$D$4:$D$274)) -> 0.28066038
A26: Althaf A | B26: 25-27 | C26: 118 | D26: =IFERROR(C26/'Owner Totals (Pivot)(Task 4)'!B7,"") -> 0.27830189 | E26: 84 | F26: 68 | G26: 58 | H26: =IFERROR(G26/C26,"") -> 0.49152542 | I26: Needs Attention | K26: =SUMPRODUCT(MAX(($A$4:$A$274=A26)*$D$4:$D$274)) -> 0.28066038
A27: Althaf A | B27: 28-29 | C27: 68 | D27: =IFERROR(C27/'Owner Totals (Pivot)(Task 4)'!B7,"") -> 0.16037736 | E27: 47 | F27: 39 | G27: 31 | H27: =IFERROR(G27/C27,"") -> 0.45588235 | K27: =SUMPRODUCT(MAX(($A$4:$A$274=A27)*$D$4:$D$274)) -> 0.28066038
A28: Althaf A | B28: 30-34 | C28: 119 | D28: =IFERROR(C28/'Owner Totals (Pivot)(Task 4)'!B7,"") -> 0.28066038 | E28: 98 | F28: 74 | G28: 72 | H28: =IFERROR(G28/C28,"") -> 0.60504202 | K28: =SUMPRODUCT(MAX(($A$4:$A$274=A28)*$D$4:$D$274)) -> 0.28066038
A29: Althaf A | B29: 35-39 | C29: 62 | D29: =IFERROR(C29/'Owner Totals (Pivot)(Task 4)'!B7,"") -> 0.14622642 | E29: 49 | F29: 42 | G29: 41 | H29: =IFERROR(G29/C29,"") -> 0.66129032 | K29: =SUMPRODUCT(MAX(($A$4:$A$274=A29)*$D$4:$D$274)) -> 0.28066038
A30: Althaf A | B30: 40-44 | C30: 26 | D30: =IFERROR(C30/'Owner Totals (Pivot)(Task 4)'!B7,"") -> 0.061320755 | E30: 22 | F30: 20 | G30: 18 | H30: =IFERROR(G30/C30,"") -> 0.69230769 | K30: =SUMPRODUCT(MAX(($A$4:$A$274=A30)*$D$4:$D$274)) -> 0.28066038
A31: Althaf A | B31: 45-49 | C31: 20 | D31: =IFERROR(C31/'Owner Totals (Pivot)(Task 4)'!B7,"") -> 0.047169811 | E31: 18 | F31: 16 | G31: 15 | H31: =IFERROR(G31/C31,"") -> 0.75 | K31: =SUMPRODUCT(MAX(($A$4:$A$274=A31)*$D$4:$D$274)) -> 0.28066038
A32: Althaf A | B32: 50+ | C32: 10 | D32: =IFERROR(C32/'Owner Totals (Pivot)(Task 4)'!B7,"") -> 0.023584906 | E32: 8 | F32: 7 | G32: 5 | H32: =IFERROR(G32/C32,"") -> 0.5 | K32: =SUMPRODUCT(MAX(($A$4:$A$274=A32)*$D$4:$D$274)) -> 0.28066038
A33: Amit B | B33: 25-27 | C33: 6 | D33: =IFERROR(C33/'Owner Totals (Pivot)(Task 4)'!B8,"") -> 0.3 | E33: 3 | F33: 3 | G33: 3 | H33: =IFERROR(G33/C33,"") -> 0.5 | I33: Needs Attention | K33: =SUMPRODUCT(MAX(($A$4:$A$274=A33)*$D$4:$D$274)) -> 0.35
A34: Amit B | B34: 28-29 | C34: 2 | D34: =IFERROR(C34/'Owner Totals (Pivot)(Task 4)'!B8,"") -> 0.1 | E34: 2 | F34: 2 | G34: 2 | H34: =IFERROR(G34/C34,"") -> 1 | K34: =SUMPRODUCT(MAX(($A$4:$A$274=A34)*$D$4:$D$274)) -> 0.35
A35: Amit B | B35: 30-34 | C35: 7 | D35: =IFERROR(C35/'Owner Totals (Pivot)(Task 4)'!B8,"") -> 0.35 | E35: 6 | F35: 5 | G35: 5 | H35: =IFERROR(G35/C35,"") -> 0.71428571 | K35: =SUMPRODUCT(MAX(($A$4:$A$274=A35)*$D$4:$D$274)) -> 0.35
A36: Amit B | B36: 35-39 | C36: 2 | D36: =IFERROR(C36/'Owner Totals (Pivot)(Task 4)'!B8,"") -> 0.1 | E36: 2 | F36: 2 | G36: 2 | H36: =IFERROR(G36/C36,"") -> 1 | K36: =SUMPRODUCT(MAX(($A$4:$A$274=A36)*$D$4:$D$274)) -> 0.35
A37: Amit B | B37: 45-49 | C37: 2 | D37: =IFERROR(C37/'Owner Totals (Pivot)(Task 4)'!B8,"") -> 0.1 | E37: 2 | F37: 2 | G37: 2 | H37: =IFERROR(G37/C37,"") -> 1 | K37: =SUMPRODUCT(MAX(($A$4:$A$274=A37)*$D$4:$D$274)) -> 0.35
A38: Amit B | B38: 50+ | C38: 1 | D38: =IFERROR(C38/'Owner Totals (Pivot)(Task 4)'!B8,"") -> 0.05 | E38: 1 | F38: 1 | G38: 1 | H38: =IFERROR(G38/C38,"") -> 1 | K38: =SUMPRODUCT(MAX(($A$4:$A$274=A38)*$D$4:$D$274)) -> 0.35
A39: Ankit V | B39: 25-27 | C39: 17 | D39: =IFERROR(C39/'Owner Totals (Pivot)(Task 4)'!B9,"") -> 0.10059172 | E39: 14 | F39: 6 | G39: 4 | H39: =IFERROR(G39/C39,"") -> 0.23529412 | I39: Needs Attention | K39: =SUMPRODUCT(MAX(($A$4:$A$274=A39)*$D$4:$D$274)) -> 0.29585799
A40: Ankit V | B40: 28-29 | C40: 14 | D40: =IFERROR(C40/'Owner Totals (Pivot)(Task 4)'!B9,"") -> 0.082840237 | E40: 13 | F40: 12 | G40: 8 | H40: =IFERROR(G40/C40,"") -> 0.57142857 | K40: =SUMPRODUCT(MAX(($A$4:$A$274=A40)*$D$4:$D$274)) -> 0.29585799
...

Sheet Owner Totals (Pivot)(Task 4)
A1: Owner-wise Totals — June 2023 | Millennium Organisation
A2: All totals calculated live via SUMIF from the "Donor Data" sheet
A3: Owner | B3: Total Submissions | C3: Total Debit 1 | D3: Total Debit 2 | E3: Total Debit 3 | F3: Overall Quality % | G3: Volume Rank
A4: Abhijeet D | B4: =SUMIF('Donor Data (Task 1,2,3,4, 6)'!$A$4:$A$274,A4,'Donor Data (Task 1,2,3,4, 6)'!$C$4:$C$274) -> 236 | C4: =SUMIF('Donor Data (Task 1,2,3,4, 6)'!$A$4:$A$274,A4,'Donor Data (Task 1,2,3,4, 6)'!$E$4:$E$274) -> 215 | D4: =SUMIF('Donor Data (Task 1,2,3,4, 6)'!$A$4:$A$274,A4,'Donor Data (Task 1,2,3,4, 6)'!$F$4:$F$274) -> 188 | E4: =SUMIF('Donor Data (Task 1,2,3,4, 6)'!$A$4:$A$274,A4,'Donor Data (Task 1,2,3,4, 6)'!$G$4:$G$274) -> 183 | F4: =IFERROR(E4/B4,"") -> 0.77542373 | G4: =RANK(B4,$B$4:$B$44) -> 18
A5: Adnan Kantawala | B5: =SUMIF('Donor Data (Task 1,2,3,4, 6)'!$A$4:$A$274,A5,'Donor Data (Task 1,2,3,4, 6)'!$C$4:$C$274) -> 114 | C5: =SUMIF('Donor Data (Task 1,2,3,4, 6)'!$A$4:$A$274,A5,'Donor Data (Task 1,2,3,4, 6)'!$E$4:$E$274) -> 93 | D5: =SUMIF('Donor Data (Task 1,2,3,4, 6)'!$A$4:$A$274,A5,'Donor Data (Task 1,2,3,4, 6)'!$F$4:$F$274) -> 76 | E5: =SUMIF('Donor Data (Task 1,2,3,4, 6)'!$A$4:$A$274,A5,'Donor Data (Task 1,2,3,4, 6)'!$G$4:$G$274) -> 65 | F5: =IFERROR(E5/B5,"") -> 0.57017544 | G5: =RANK(B5,$B$4:$B$44) -> 28
A6: Ajay M | B6: =SUMIF('Donor Data (Task 1,2,3,4, 6)'!$A$4:$A$274,A6,'Donor Data (Task 1,2,3,4, 6)'!$C$4:$C$274) -> 104 | C6: =SUMIF('Donor Data (Task 1,2,3,4, 6)'!$A$4:$A$274,A6,'Donor Data (Task 1,2,3,4, 6)'!$E$4:$E$274) -> 87 | D6: =SUMIF('Donor Data (Task 1,2,3,4, 6)'!$A$4:$A$274,A6,'Donor Data (Task 1,2,3,4, 6)'!$F$4:$F$274) -> 70 | E6: =SUMIF('Donor Data (Task 1,2,3,4, 6)'!$A$4:$A$274,A6,'Donor Data (Task 1,2,3,4, 6)'!$G$4:$G$274) -> 66 | F6: =IFERROR(E6/B6,"") -> 0.63461538 | G6: =RANK(B6,$B$4:$B$44) -> 29
A7: Althaf A | B7: =SUMIF('Donor Data (Task 1,2,3,4, 6)'!$A$4:$A$274,A7,'Donor Data (Task 1,2,3,4, 6)'!$C$4:$C$274) -> 424 | C7: =SUMIF('Donor Data (Task 1,2,3,4, 6)'!$A$4:$A$274,A7,'Donor Data (Task 1,2,3,4, 6)'!$E$4:$E$274) -> 326 | D7: =SUMIF('Donor Data (Task 1,2,3,4, 6)'!$A$4:$A$274,A7,'Donor Data (Task 1,2,3,4, 6)'!$F$4:$F$274) -> 266 | E7: =SUMIF('Donor Data (Task 1,2,3,4, 6)'!$A$4:$A$274,A7,'Donor Data (Task 1,2,3,4, 6)'!$G$4:$G$274) -> 240 | F7: =IFERROR(E7/B7,"") -> 0.56603774 | G7: =RANK(B7,$B$4:$B$44) -> 4
A8: Amit B | B8: =SUMIF('Donor Data (Task 1,2,3,4, 6)'!$A$4:$A$274,A8,'Donor Data (Task 1,2,3,4, 6)'!$C$4:$C$274) -> 20 | C8: =SUMIF('Donor Data (Task 1,2,3,4, 6)'!$A$4:$A$274,A8,'Donor Data (Task 1,2,3,4, 6)'!$E$4:$E$274) -> 16 | D8: =SUMIF('Donor Data (Task 1,2,3,4, 6)'!$A$4:$A$274,A8,'Donor Data (Task 1,2,3,4, 6)'!$F$4:$F$274) -> 15 | E8: =SUMIF('Donor Data (Task 1,2,3,4, 6)'!$A$4:$A$274,A8,'Donor Data (Task 1,2,3,4, 6)'!$G$4:$G$274) -> 15 | F8: =IFERROR(E8/B8,"") -> 0.75 | G8: =RANK(B8,$B$4:$B$44) -> 38
A9: Ankit V | B9: =SUMIF('Donor Data (Task 1,2,3,4, 6)'!$A$4:$A$274,A9,'Donor Data (Task 1,2,3,4, 6)'!$C$4:$C$274) -> 169 | C9: =SUMIF('Donor Data (Task 1,2,3,4, 6)'!$A$4:$A$274,A9,'Donor Data (Task 1,2,3,4, 6)'!$E$4:$E$274) -> 142 | D9: =SUMIF('Donor Data (Task 1,2,3,4, 6)'!$A$4:$A$274,A9,'Donor Data (Task 1,2,3,4, 6)'!$F$4:$F$274) -> 120 | E9: =SUMIF('Donor Data (Task 1,2,3,4, 6)'!$A$4:$A$274,A9,'Donor Data (Task 1,2,3,4, 6)'!$G$4:$G$274) -> 103 | F9: =IFERROR(E9/B9,"") -> 0.60946746 | G9: =RANK(B9,$B$4:$B$44) -> 23
A10: Arun Kumar D | B10: =SUMIF('Donor Data (Task 1,2,3,4, 6)'!$A$4:$A$274,A10,'Donor Data (Task 1,2,3,4, 6)'!$C$4:$C$274) -> 272 | C10: =SUMIF('Donor Data (Task 1,2,3,4, 6)'!$A$4:$A$274,A10,'Donor Data (Task 1,2,3,4, 6)'!$E$4:$E$274) -> 240 | D10: =SUMIF('Donor Data (Task 1,2,3,4, 6)'!$A$4:$A$274,A10,'Donor Data (Task 1,2,3,4, 6)'!$F$4:$F$274) -> 201 | E10: =SUMIF('Donor Data (Task 1,2,3,4, 6)'!$A$4:$A$274,A10,'Donor Data (Task 1,2,3,4, 6)'!$G$4:$G$274) -> 192 | F10: =IFERROR(E10/B10,"") -> 0.70588235 | G10: =RANK(B10,$B$4:$B$44) -> 15
A11: Arvind S | B11: =SUMIF('Donor Data (Task 1,2,3,4, 6)'!$A$4:$A$274,A11,'Donor Data (Task 1,2,3,4, 6)'!$C$4:$C$274) -> 59 | C11: =SUMIF('Donor Data (Task 1,2,3,4, 6)'!$A$4:$A$274,A11,'Donor Data (Task 1,2,3,4, 6)'!$E$4:$E$274) -> 46 | D11: =SUMIF('Donor Data (Task 1,2,3,4, 6)'!$A$4:$A$274,A11,'Donor Data (Task 1,2,3,4, 6)'!$F$4:$F$274) -> 32 | E11: =SUMIF('Donor Data (Task 1,2,3,4, 6)'!$A$4:$A$274,A11,'Donor Data (Task 1,2,3,4, 6)'!$G$4:$G$274) -> 26 | F11: =IFERROR(E11/B11,"") -> 0.44067797 | G11: =RANK(B11,$B$4:$B$44) -> 34
A12: D Dinesh | B12: =SUMIF('Donor Data (Task 1,2,3,4, 6)'!$A$4:$A$274,A12,'Donor Data (Task 1,2,3,4, 6)'!$C$4:$C$274) -> 574 | C12: =SUMIF('Donor Data (Task 1,2,3,4, 6)'!$A$4:$A$274,A12,'Donor Data (Task 1,2,3,4, 6)'!$E$4:$E$274) -> 520 | D12: =SUMIF('Donor Data (Task 1,2,3,4, 6)'!$A$4:$A$274,A12,'Donor Data (Task 1,2,3,4, 6)'!$F$4:$F$274) -> 449 | E12: =SUMIF('Donor Data (Task 1,2,3,4, 6)'!$A$4:$A$274,A12,'Donor Data (Task 1,2,3,4, 6)'!$G$4:$G$274) -> 398 | F12: =IFERROR(E12/B12,"") -> 0.69337979 | G12: =RANK(B12,$B$4:$B$44) -> 1
A13: Gargi Y | B13: =SUMIF('Donor Data (Task 1,2,3,4, 6)'!$A$4:$A$274,A13,'Donor Data (Task 1,2,3,4, 6)'!$C$4:$C$274) -> 75 | C13: =SUMIF('Donor Data (Task 1,2,3,4, 6)'!$A$4:$A$274,A13,'Donor Data (Task 1,2,3,4, 6)'!$E$4:$E$274) -> 67 | D13: =SUMIF('Donor Data (Task 1,2,3,4, 6)'!$A$4:$A$274,A13,'Donor Data (Task 1,2,3,4, 6)'!$F$4:$F$274) -> 57 | E13: =SUMIF('Donor Data (Task 1,2,3,4, 6)'!$A$4:$A$274,A13,'Donor Data (Task 1,2,3,4, 6)'!$G$4:$G$274) -> 50 | F13: =IFERROR(E13/B13,"") -> 0.66666667 | G13: =RANK(B13,$B$4:$B$44) -> 32
A14: Hamza KMS | B14: =SUMIF('Donor Data (Task 1,2,3,4, 6)'!$A$4:$A$274,A14,'Donor Data (Task 1,2,3,4, 6)'!$C$4:$C$274) -> 344 | C14: =SUMIF('Donor Data (Task 1,2,3,4, 6)'!$A$4:$A$274,A14,'Donor Data (Task 1,2,3,4, 6)'!$E$4:$E$274) -> 276 | D14: =SUMIF('Donor Data (Task 1,2,3,4, 6)'!$A$4:$A$274,A14,'Donor Data (Task 1,2,3,4, 6)'!$F$4:$F$274) -> 232 | E14: =SUMIF('Donor Data (Task 1,2,3,4, 6)'!$A$4:$A$274,A14,'Donor Data (Task 1,2,3,4, 6)'!$G$4:$G$274) -> 211 | F14: =IFERROR(E14/B14,"") -> 0.61337209 | G14: =RANK(B14,$B$4:$B$44) -> 9
A15: Jagannathan K | B15: =SUMIF('Donor Data (Task 1,2,3,4, 6)'!$A$4:$A$274,A15,'Donor Data (Task 1,2,3,4, 6)'!$C$4:$C$274) -> 25 | C15: =SUMIF('Donor Data (Task 1,2,3,4, 6)'!$A$4:$A$274,A15,'Donor Data (Task 1,2,3,4, 6)'!$E$4:$E$274) -> 24 | D15: =SUMIF('Donor Data (Task 1,2,3,4, 6)'!$A$4:$A$274,A15,'Donor Data (Task 1,2,3,4, 6)'!$F$4:$F$274) -> 20 | E15: =SUMIF('Donor Data (Task 1,2,3,4, 6)'!$A$4:$A$274,A15,'Donor Data (Task 1,2,3,4, 6)'!$G$4:$G$274) -> 17 | F15: =IFERROR(E15/B15,"") -> 0.68 | G15: =RANK(B15,$B$4:$B$44) -> 37
... A44: Yash P | B44: =SUMIF('Donor Data (Task 1,2,3,4, 6)'!$A$4:$A$274,A44,'Donor Data (Task 1,2,3,4, 6)'!$C$4:$C$274) -> 361 | C44: =SUMIF('Donor Data (Task 1,2,3,4, 6)'!$A$4:$A$274,A44,'Donor Data (Task 1,2,3,4, 6)'!$E$4:$E$274) -> 295 | D44: =SUMIF('Donor Data (Task 1,2,3,4, 6)'!$A$4:$A$274,A44,'Donor Data (Task 1,2,3,4, 6)'!$F$4:$F$274) -> 242 | E44: =SUMIF('Donor Data (Task 1,2,3,4, 6)'!$A$4:$A$274,A44,'Donor Data (Task 1,2,3,4, 6)'!$G$4:$G$274) -> 204 | F44: =IFERROR(E44/B44,"") -> 0.56509695 | G44: =RANK(B44,$B$4:$B$44) -> 7
A45: Grand Total | B45: =SUM(B4:B44) -> 8786 | C45: =SUM(C4:C44) -> 7620 | D45: =SUM(D4:D44) -> 6576 | E45: =SUM(E4:E44) -> 5936 | F45: =IFERROR(E45/B45,"") -> 0.67562031
A47: ▌ Owner Submissions vs Final Debit (Debit 3)

Sheet Owner Performance(Task 5)
A1: Owner Performance Summary — June 2023
A2: Quality = Debit 3% (Debit3/Submission) | Volume = Total Submissions | ⭐ = Top performers
A3: Owner | B3: Total Submissions | C3: Debit 3 (Final) | D3: Overall Quality % | E3: Volume Rank | F3: Quality Rank | G3: Verdict
A4: D Dinesh | B4: 574 | C4: 398 | D4: 0.69337979 | E4: 1 | F4: 16 | G4: High Volume
A5: Surendran R | B5: 536 | C5: 356 | D5: 0.6641791 | E5: 2 | F5: 23 | G5: High Volume
A6: Sai Lakshmi V | B6: 519 | C6: 392 | D6: 0.75529865 | E6: 3 | F6: 7 | G6: High Volume
A7: Althaf A | B7: 424 | C7: 240 | D7: 0.56603774 | E7: 4 | F7: 37 | G7: High Volume
A8: Pooja D | B8: 408 | C8: 249 | D8: 0.61029412 | E8: 5 | F8: 31 | G8: High Volume
A9: Rohit R | B9: 383 | C9: 253 | D9: 0.66057441 | E9: 6 | F9: 24 | G9: High Volume
A10: Yash P | B10: 361 | C10: 204 | D10: 0.56509695 | E10: 7 | F10: 38 | G10: High Volume
A11: Sandhya P | B11: 354 | C11: 245 | D11: 0.6920904 | E11: 8 | F11: 17 | G11: High Volume
A12: Hamza KMS | B12: 344 | C12: 211 | D12: 0.61337209 | E12: 9 | F12: 30 | G12: High Volume
A13: MILLENNIUM | B13: 332 | C13: 266 | D13: 0.80120482 | E13: 10 | F13: 2 | G13: High Volume
A14: Sumitha P | B14: 313 | C14: 209 | D14: 0.66773163 | E14: 11 | F14: 21 | G14: Average
A15: Mayank S | B15: 298 | C15: 199 | D15: 0.66778523 | E15: 12 | F15: 20 | G15: Average
... A44: Sukesh K | B44: 3 | C44: 0 | D44: 0 | E44: 41 | F44: 41 | G44: Low Quality
A47: No owner currently ranks in the top 5 for both volume and quality, suggesting a trade-off between scale and conversion efficiency that leadership may want to address. Verdict logic: Owners are ranked against each other on two dimensions — Volume Rank (by total submissions) and Quality Rank (by Debit 3%, i.e., donor retention rate). Top Performer: ranks in the top 5 for both volume and quality High Volume: ranks in the top 10 by total submissions High Quality: ranks in the top 5 by Debit 3% Low Quality: overall Debit 3% below 65% Average: does not meet any of the above criteria

Sheet Age Group Insights(Task 6)
A1: Age Group Analysis — Which Age Bands Drive Quality & Volume?
A2: Age Group | B2: Total Submissions | C2: Total Debit 1 | D2: Total Debit 3 | E2: Drop-off D1→D3 | F2: Overall Quality %
A3: BELOW 25 | B3: 4 | C3: 2 | D3: 0 | E3: 1 | F3: 0
A4: 25-27 | B4: 1546 | C4: 1236 | D4: 856 | E4: 0.30744337 | F4: 0.55368693
A5: 28-29 | B5: 1378 | C5: 1147 | D5: 826 | E5: 0.27986051 | F5: 0.59941945
A6: 30-34 | B6: 2843 | C6: 2483 | D6: 1890 | E6: 0.238824 | F6: 0.66479071
A7: 35-39 | B7: 1488 | C7: 1337 | D7: 1123 | E7: 0.16005984 | F7: 0.7547043
A8: 40-44 | B8: 791 | C8: 735 | D8: 637 | E8: 0.13333333 | F8: 0.80530973
A9: 45-49 | B9: 371 | C9: 344 | D9: 304 | E9: 0.11627907 | F9: 0.81940701
A10: 50+ | B10: 366 | C10: 337 | D10: 300 | E10: 0.10979228 | F10: 0.81967213
A13: 💡 Key Insight: 30-34 age band drives the highest submission volume. 50+ group shows the best retention (lowest drop-off). 25-27 has highest absolute volume but variable quality across owners.
